Workbook

Sheet All_India_Index_Upto_April23 (1
A1: Sector | B1: Year | C1: Month | D1: Cereals and products | E1: Meat and fish | F1: Egg | G1: Milk and products | H1: Oils and fats | I1: Fruits | J1: Vegetables | K1: Pulses and products | L1: Sugar and Confectionery | M1: Spices | N1: Non-alcoholic beverages | O1: Prepared meals, snacks, sweets etc. | P1: Food and beverages | Q1: Pan, tobacco and intoxicants | R1: Clothing | S1: Footwear | T1: Clothing and footwear | U1: Housing | V1: Fuel and light | W1: Household goods and services | X1: Health | Y1: Transport and communication | Z1: Recreation and amusement | AA1: Education | AB1: Personal care and effects | AC1: Miscellaneous | AD1: General index | AF1: CEREAL INFLATION
A2: Rural | B2: 2013 | C2: January | D2: 107.5 | E2: 106.3 | F2: 108.1 | G2: 104.9 | H2: 106.1 | I2: 103.9 | J2: 101.9 | K2: 106.1 | L2: 106.8 | M2: 103.1 | N2: 104.8 | O2: 106.7 | P2: 105.5 | Q2: 105.1 | R2: 106.5 | S2: 105.8 | T2: 106.4 | U2: 0 | V2: 105.5 | W2: 104.8 | X2: 104 | Y2: 103.3 | Z2: 103.4 | AA2: 103.8 | AB2: 104.7 | AC2: 104 | AD2: 105.1 | AF2: =(D3-D2)/D2*100 -> 2.7906977
A3: Urban | B3: 2013 | C3: January | D3: 110.5 | E3: 109.1 | F3: 113 | G3: 103.6 | H3: 103.4 | I3: 102.3 | J3: 102.9 | K3: 105.8 | L3: 105.1 | M3: 101.8 | N3: 105.1 | O3: 107.9 | P3: 105.9 | Q3: 105.2 | R3: 105.9 | S3: 105 | T3: 105.8 | U3: 100.3 | V3: 105.4 | W3: 104.8 | X3: 104.1 | Y3: 103.2 | Z3: 102.9 | AA3: 103.5 | AB3: 104.3 | AC3: 103.7 | AD3: 104 | AF3: =(D4-D3)/D3*100 -> -1.9004525
A4: Rural+Urban | B4: 2013 | C4: January | D4: 108.4 | E4: 107.3 | F4: 110 | G4: 104.4 | H4: 105.1 | I4: 103.2 | J4: 102.2 | K4: 106 | L4: 106.2 | M4: 102.7 | N4: 104.9 | O4: 107.3 | P4: 105.6 | Q4: 105.1 | R4: 106.3 | S4: 105.5 | T4: 106.2 | U4: 100.3 | V4: 105.5 | W4: 104.8 | X4: 104 | Y4: 103.2 | Z4: 103.1 | AA4: 103.6 | AB4: 104.5 | AC4: 103.9 | AD4: 104.6 | AF4: =(D5-D4)/D4*100 -> 0.73800738
A5: Rural | B5: 2013 | C5: February | D5: 109.2 | E5: 108.7 | F5: 110.2 | G5: 105.4 | H5: 106.7 | I5: 104 | J5: 102.4 | K5: 105.9 | L5: 105.7 | M5: 103.1 | N5: 105.1 | O5: 107.7 | P5: 106.3 | Q5: 105.6 | R5: 107.1 | S5: 106.3 | T5: 107 | U5: 0 | V5: 106.2 | W5: 105.2 | X5: 104.4 | Y5: 103.9 | Z5: 104 | AA5: 104.1 | AB5: 104.6 | AC5: 104.4 | AD5: 105.8 | AF5: =(D6-D5)/D5*100 -> 3.3882784
A6: Urban | B6: 2013 | C6: February | D6: 112.9 | E6: 112.9 | F6: 116.9 | G6: 104 | H6: 103.5 | I6: 103.1 | J6: 104.9 | K6: 104.1 | L6: 103.8 | M6: 102.3 | N6: 106 | O6: 109 | P6: 107.2 | Q6: 106 | R6: 106.6 | S6: 105.5 | T6: 106.4 | U6: 100.4 | V6: 105.7 | W6: 105.2 | X6: 104.7 | Y6: 104.4 | Z6: 103.3 | AA6: 103.7 | AB6: 104.3 | AC6: 104.3 | AD6: 104.7 | AF6: =(D7-D6)/D6*100 -> -2.214349
A7: Rural+Urban | B7: 2013 | C7: February | D7: 110.4 | E7: 110.2 | F7: 112.8 | G7: 104.9 | H7: 105.5 | I7: 103.6 | J7: 103.2 | K7: 105.3 | L7: 105.1 | M7: 102.8 | N7: 105.5 | O7: 108.3 | P7: 106.6 | Q7: 105.7 | R7: 106.9 | S7: 106 | T7: 106.8 | U7: 100.4 | V7: 106 | W7: 105.2 | X7: 104.5 | Y7: 104.2 | Z7: 103.6 | AA7: 103.9 | AB7: 104.5 | AC7: 104.4 | AD7: 105.3 | AF7: =(D8-D7)/D7*100 -> -0.18115942
A8: Rural | B8: 2013 | C8: March | D8: 110.2 | E8: 108.8 | F8: 109.9 | G8: 105.6 | H8: 106.2 | I8: 105.7 | J8: 101.4 | K8: 105.7 | L8: 105 | M8: 103.3 | N8: 105.6 | O8: 108.2 | P8: 106.6 | Q8: 106.5 | R8: 107.6 | S8: 106.8 | T8: 107.5 | U8: 0 | V8: 106.1 | W8: 105.6 | X8: 104.7 | Y8: 104.6 | Z8: 104 | AA8: 104.3 | AB8: 104.3 | AC8: 104.6 | AD8: 106 | AF8: =(D9-D8)/D8*100 -> 3.3575318
A9: Urban | B9: 2013 | C9: March | D9: 113.9 | E9: 111.4 | F9: 113.2 | G9: 104.3 | H9: 102.7 | I9: 104.9 | J9: 103.8 | K9: 103.5 | L9: 102.6 | M9: 102.4 | N9: 107 | O9: 109.8 | P9: 107.3 | Q9: 106.8 | R9: 107.2 | S9: 106 | T9: 107 | U9: 100.4 | V9: 106 | W9: 105.7 | X9: 105.2 | Y9: 105.5 | Z9: 103.5 | AA9: 103.8 | AB9: 104.2 | AC9: 104.9 | AD9: 105 | AF9: =(D10-D9)/D9*100 -> -2.1949078
A10: Rural+Urban | B10: 2013 | C10: March | D10: 111.4 | E10: 109.7 | F10: 111.2 | G10: 105.1 | H10: 104.9 | I10: 105.3 | J10: 102.2 | K10: 105 | L10: 104.2 | M10: 103 | N10: 106.2 | O10: 108.9 | P10: 106.9 | Q10: 106.6 | R10: 107.4 | S10: 106.5 | T10: 107.3 | U10: 100.4 | V10: 106.1 | W10: 105.6 | X10: 104.9 | Y10: 105.1 | Z10: 103.7 | AA10: 104 | AB10: 104.3 | AC10: 104.7 | AD10: 105.5 | AF10: =(D11-D10)/D10*100 -> -1.0771993
A11: Rural | B11: 2013 | C11: April | D11: 110.2 | E11: 109.5 | F11: 106.9 | G11: 106.3 | H11: 105.7 | I11: 108.3 | J11: 103.4 | K11: 105.7 | L11: 104.2 | M11: 103.2 | N11: 106.5 | O11: 108.8 | P11: 107.1 | Q11: 107.1 | R11: 108.1 | S11: 107.4 | T11: 108 | U11: 0 | V11: 106.5 | W11: 106.1 | X11: 105.1 | Y11: 104.4 | Z11: 104.5 | AA11: 104.8 | AB11: 102.7 | AC11: 104.6 | AD11: 106.4 | AF11: =(D12-D11)/D11*100 -> 3.9927405
A12: Urban | B12: 2013 | C12: April | D12: 114.6 | E12: 113.4 | F12: 106 | G12: 104.7 | H12: 102.1 | I12: 109.5 | J12: 109.7 | K12: 104.6 | L12: 102 | M12: 103.5 | N12: 108.2 | O12: 110.6 | P12: 108.8 | Q12: 108.5 | R12: 107.9 | S12: 106.4 | T12: 107.7 | U12: 100.5 | V12: 106.4 | W12: 106.5 | X12: 105.7 | Y12: 105 | Z12: 104 | AA12: 105.2 | AB12: 103.2 | AC12: 105.1 | AD12: 105.7 | AF12: =(D13-D12)/D12*100 -> -2.617801
A13: Rural+Urban | B13: 2013 | C13: April | D13: 111.6 | E13: 110.9 | F13: 106.6 | G13: 105.7 | H13: 104.4 | I13: 108.9 | J13: 105.5 | K13: 105.3 | L13: 103.5 | M13: 103.3 | N13: 107.2 | O13: 109.6 | P13: 107.7 | Q13: 107.5 | R13: 108 | S13: 107 | T13: 107.9 | U13: 100.5 | V13: 106.5 | W13: 106.3 | X13: 105.3 | Y13: 104.7 | Z13: 104.2 | AA13: 105 | AB13: 102.9 | AC13: 104.8 | AD13: 106.1 | AF13: =(D14-D13)/D13*100 -> -0.62724014
... A261: Urban | B261: 2020 | C261: April | D261: 151.8 | E261: 167.4 | F261: 151.9 | G261: 155.5 | H261: 131.6 | I261: 152.9 | J261: 180 | K261: 150.8 | L261: 121.2 | M261: 154 | N261: 133.5 | O261: 159.1 | P261: 153.5 | Q261: 170.7 | R261: 150.1 | S261: 139.8 | T261: 148.4 | U261: 155.6 | V261: 137.1 | W261: 145.3 | X261: 144.8 | Y261: 129.8 | Z261: 142.9 | AA261: 156 | AB261: 143.7 | AC261: 142.7 | AD261: 148.9 | AF261: =(D262-D261)/D261*100 -> -2.0421607
A262: Rural+Urban | B262: 2020 | C262: April | D262: 148.7 | E262: 167.3 | F262: 148.8 | G262: 155.6 | H262: 135.1 | I262: 149.9 | J262: 168.6 | K262: 150.4 | L262: 120.3 | M262: 157.1 | N262: 136.8 | O262: 159.2 | P262: 151.4 | Q262: 170.8 | R262: 150.5 | S262: 141 | T262: 149.1 | U262: 155.6 | V262: 144.1 | W262: 146.2 | X262: 150.7 | Y262: 130.3 | Z262: 143.8 | AA262: =AVERAGE(AA253:AA259) -> 156.6 | AB262: 144 | AC262: 143.5 | AD262: 149 | AF262: =(D263-D262)/D262*100 -> -2.3537323
A263: Rural | B263: 2020 | C263: May | D263: =AVERAGE(D251:D260) -> 145.2 | E263: 167.3 | F263: 151.1 | G263: 151.2 | H263: 130.9 | I263: 143 | J263: 175.3 | K263: 141.5 | L263: 114.4 | M263: 152.4 | N263: 136.2 | O263: 159 | P263: 151 | Q263: 170.5 | R263: 150.4 | S263: 140.9 | T263: 149 | U263: 0 | V263: 146 | W263: 146.2 | X263: 150.5 | Y263: 130.6 | Z263: 143.8 | AA263: 156.7 | AB263: 143.5 | AC263: 143.5 | AD263: 149.2 | AF263: =(D264-D263)/D263*100 -> 0.55096419
A264: Urban | B264: 2020 | C264: May | D264: 146 | E264: 167.3 | F264: 151.1 | G264: 151.7 | H264: 130.9 | I264: =AVERAGE(I252:I261) -> 144.1 | J264: 174.1 | K264: 142.5 | L264: 115.1 | M264: =AVERAGE(M252:M261) -> 152.7 | N264: 135.6 | O264: 159.1 | P264: 151 | Q264: 170.7 | R264: 150.1 | S264: 140.2 | T264: 148.6 | U264: 108.2 | V264: 144.7 | W264: 145.5 | X264: 150 | Y264: 130 | Z264: 143.1 | AA264: 156.1 | AB264: 143.7 | AC264: 143 | AD264: 148.9 | AF264: =(D265-D264)/D264*100 -> 0.20547945
A265: Rural+Urban | B265: 2020 | C265: May | D265: 146.3 | E265: 167.3 | F265: 150.2 | G265: 152.3 | H265: 131.8 | I265: =AVERAGE(I253:I264) -> 144.46667 | J265: 170.2 | K265: 143.6 | L265: 115.6 | M265: 153.3 | N265: 136.2 | O265: =AVERAGE(O253:O262) -> 159.19 | P265: 150.7 | Q265: 170.7 | R265: 150.5 | S265: 141.1 | T265: 149.1 | U265: =AVERAGE(U253:U262) -> 108.37 | V265: 145.6 | W265: 146.2 | X265: 150.7 | Y265: =AVERAGE(Y253:Y262) -> 130.43 | Z265: 143.9 | AA265: 156.6 | AB265: 143.9 | AC265: 143.6 | AD265: 149 | AF265: =(D266-D265)/D265*100 -> 1.2987013
A266: Rural | B266: 2020 | C266: June | D266: 148.2 | E266: 190.3 | F266: 149.4 | G266: 153.3 | H266: 138.2 | I266: 143.2 | J266: 148.9 | K266: 150.3 | L266: 113.2 | M266: 159.8 | N266: 142.1 | O266: 161.8 | P266: 152.3 | Q266: 182.4 | R266: 154.7 | S266: 150 | T266: 154.1 | U266: 0 | V266: 144.9 | W266: 151.7 | X266: 158.2 | Y266: 141.4 | Z266: 153.2 | AA266: 161.8 | AB266: 151.2 | AC266: 151.7 | AD266: 152.7 | AF266: =(D267-D266)/D266*100 -> 3.0364372
A267: Urban | B267: 2020 | C267: June | D267: 152.7 | E267: 197 | F267: 154.6 | G267: 153.4 | H267: 132.9 | I267: 151.8 | J267: 171.2 | K267: 152 | L267: 116.3 | M267: 158.8 | N267: 135.6 | O267: 161.7 | P267: 157 | Q267: 186.7 | R267: 149.1 | S267: 136.6 | T267: 147.2 | U267: 154.7 | V267: 137.1 | W267: 140.4 | X267: 148.1 | Y267: 129.3 | Z267: 144.5 | AA267: 152.5 | AB267: 152.2 | AC267: 142 | AD267: 150.8 | AF267: =(D268-D267)/D267*100 -> -2.0301244
A268: Rural+Urban | B268: 2020 | C268: June | D268: 149.6 | E268: 192.7 | F268: 151.4 | G268: 153.3 | H268: 136.3 | I268: 147.2 | J268: 156.5 | K268: 150.9 | L268: 114.2 | M268: 159.5 | N268: 139.4 | O268: 161.8 | P268: 154 | Q268: 183.5 | R268: 152.5 | S268: 144.4 | T268: 151.4 | U268: 154.7 | V268: 141.9 | W268: 146.4 | X268: 154.4 | Y268: 135 | Z268: 148.3 | AA268: 156.4 | AB268: 151.6 | AC268: 147 | AD268: 151.8 | AF268: =(D269-D268)/D268*100 -> -0.93582888
A269: Rural | B269: 2020 | C269: July | D269: 148.2 | E269: 190.3 | F269: 149.4 | G269: 153.3 | H269: 138.2 | I269: 143.2 | J269: 148.9 | K269: 150.3 | L269: 113.2 | M269: 159.8 | N269: 142.1 | O269: 161.8 | P269: 152.3 | Q269: 182.4 | R269: 154.7 | S269: 150 | T269: 154.1 | U269: 0 | V269: 144.9 | W269: 151.7 | X269: 158.2 | Y269: 141.4 | Z269: 153.2 | AA269: 161.8 | AB269: 151.2 | AC269: 151.7 | AD269: 152.7 | AF269: =(D270-D269)/D269*100 -> 3.0364372
A270: Urban | B270: 2020 | C270: July | D270: 152.7 | E270: 197 | F270: 154.6 | G270: 153.4 | H270: 132.9 | I270: 151.8 | J270: 171.2 | K270: 152 | L270: 116.3 | M270: 158.8 | N270: 135.6 | O270: 161.7 | P270: 157 | Q270: 186.7 | R270: 149.1 | S270: 136.6 | T270: 147.2 | U270: 154.7 | V270: 137.1 | W270: 140.4 | X270: 148.1 | Y270: 129.3 | Z270: 144.5 | AA270: 152.5 | AB270: 152.2 | AC270: 142 | AD270: 150.8 | AF270: =(D271-D270)/D270*100 -> -2.0301244
A271: Rural+Urban | B271: 2020 | C271: July | D271: 149.6 | E271: 192.7 | F271: 151.4 | G271: 153.3 | H271: 136.3 | I271: 147.2 | J271: 156.5 | K271: 150.9 | L271: 114.2 | M271: 159.5 | N271: 139.4 | O271: 161.8 | P271: 154 | Q271: 183.5 | R271: 152.5 | S271: 144.4 | T271: 151.4 | U271: 154.7 | V271: 141.9 | W271: 146.4 | X271: 154.4 | Y271: 135 | Z271: 148.3 | AA271: 156.4 | AB271: 151.6 | AC271: 147 | AD271: 151.8 | AF271: =(D272-D271)/D271*100 -> -1.3368984
A272: Rural | B272: 2020 | C272: August | D272: 147.6 | E272: 187.2 | F272: 148.4 | G272: 153.3 | H272: 139.8 | I272: 146.9 | J272: 171 | K272: 149.9 | L272: 114.2 | M272: 160 | N272: 143.5 | O272: 161.5 | P272: 155.3 | Q272: 180.9 | R272: 155.1 | S272: 149.3 | T272: 154.3 | U272: 0 | V272: 145.8 | W272: 151.9 | X272: 158.8 | Y272: 143.6 | Z272: 152.2 | AA272: 162.7 | AB272: 153.6 | AC272: 153 | AD272: 154.7 | AF272: =(D273-D272)/D272*100 -> 2.7100271
A273: Urban | B273: 2020 | C273: August | D273: 151.6 | E273: 197.8 | F273: 154.5 | G273: 153.4 | H273: 133.4 | I273: 154.5 | J273: 191.9 | K273: 151.3 | L273: 116.8 | M273: 160 | N273: 136.5 | O273: 163.3 | P273: 159.9 | Q273: 187.2 | R273: 150 | S273: 135.2 | T273: 147.8 | U273: 155.5 | V273: 138.3 | W273: 144.5 | X273: 148.7 | Y273: 133.9 | Z273: 141.2 | AA273: 155.5 | AB273: 155.2 | AC273: 144.8 | AD273: 152.9 | AF273: =(D274-D273)/D273*100 -> -1.7810026
A274: Rural+Urban | B274: 2020 | C274: August | D274: 148.9 | E274: 190.9 | F274: 150.8 | G274: 153.3 | H274: 137.4 | I274: 150.4 | J274: 178.1 | K274: 150.4 | L274: 115.1 | M274: 160 | N274: 140.6 | O274: 162.3 | P274: 157 | Q274: 182.6 | R274: 153.1 | S274: 143.4 | T274: 151.7 | U274: 155.5 | V274: 143 | W274: 148.4 | X274: 155 | Y274: 138.5 | Z274: 146 | AA274: 158.5 | AB274: 154.3 | AC274: 149 | AD274: 153.9 | AF274: =(D275-D274)/D274*100 -> -1.3431833
A275: Rural | B275: 2020 | C275: September | D275: 146.9 | E275: 183.9 | F275: 149.5 | G275: 153.4 | H275: 140.4 | I275: 147 | J275: 178.8 | K275: 149.3 | L275: 115.1 | M275: 160 | N275: 145.4 | O275: 161.6 | P275: 156.1 | Q275: 182.9 | R275: 155.4 | S275: 149.9 | T275: 154.6 | U275: 0 | V275: 146.4 | W275: 151.6 | X275: 159.1 | Y275: 144.6 | Z275: 152.8 | AA275: 161.1 | AB275: 157.4 | AC275: 153.7 | AD275: 155.4 | AF275: =(D276-D275)/D275*100 -> 3.1313819
A276: Urban | B276: 2020 | C276: September | D276: 151.5 | E276: 193.1 | F276: 157.3 | G276: 153.9 | H276: 134.4 | I276: 155.4 | J276: 202 | K276: 150.8 | L276: 118.9 | M276: 160.9 | N276: 137.7 | O276: 164.4 | P276: 161.3 | Q276: 188.7 | R276: 150.2 | S276: 136.3 | T276: 148.1 | U276: 156.3 | V276: 137.2 | W276: 145.4 | X276: 150 | Y276: 135.1 | Z276: 141.8 | AA276: 154.9 | AB276: 159.8 | AC276: 146 | AD276: 154 | AF276: =(D277-D276)/D276*100 -> -2.0462046
A277: Rural+Urban | B277: 2020 | C277: September | D277: 148.4 | E277: 187.1 | F277: 152.5 | G277: 153.6 | H277: 138.2 | I277: 150.9 | J277: 186.7 | K277: 149.8 | L277: 116.4 | M277: 160.3 | N277: 142.2 | O277: 162.9 | P277: 158 | Q277: 184.4 | R277: 153.4 | S277: 144.3 | T277: 152 | U277: 156.3 | V277: 142.9 | W277: 148.7 | X277: 155.6 | Y277: 139.6 | Z277: 146.6 | AA277: 157.5 | AB277: 158.4 | AC277: 150 | AD277: 154.7 | AF277: =(D278-D277)/D277*100 -> -1.6172507
... A292: Rural+Urban | B292: 2021 | C292: February | D292: 144.3 | E292: 186.5 | F292: 168.7 | G292: 154.7 | H292: 158.7 | I292: 150.7 | J292: 160 | K292: 158.8 | L292: 112.8 | M292: 164.2 | N292: 155.5 | O292: 167.5 | P292: 156.9 | Q292: 188.3 | R292: 157.2 | S292: 147.4 | T292: 155.8 | U292: 159.8 | V292: 152.4 | W292: 150.9 | X292: 161.3 | Y292: 145.1 | Z292: 151.5 | AA292: 159.5 | AB292: 155.8 | AC292: 153.4 | AD292: 156.6 | AF292: =(D293-D292)/D292*100 -> -1.2474012
A293: Rural | B293: 2021 | C293: March | D293: 142.5 | E293: 189.4 | F293: 163.2 | G293: 154.5 | H293: 168.2 | I293: 150.5 | J293: 141 | K293: 159.2 | L293: 111.7 | M293: 164 | N293: 160.6 | O293: 166.4 | P293: 154.5 | Q293: 186.1 | R293: 159.6 | S293: 154.4 | T293: 158.9 | U293: - | V293: 156 | W293: 154.8 | X293: 164.6 | Y293: 151.3 | Z293: 157.8 | AA293: 163.8 | AB293: 153.1 | AC293: 157.3 | AD293: 156.7 | AF293: =(D294-D293)/D293*100 -> 3.5087719
A294: Urban | B294: 2021 | C294: March | D294: 147.5 | E294: 197.5 | F294: 164.7 | G294: 155.6 | H294: 156.4 | I294: 157.3 | J294: 166.1 | K294: 161.1 | L294: 114.3 | M294: 162.6 | N294: 150.7 | O294: 170.3 | P294: 160.4 | Q294: 193.5 | R294: 155.1 | S294: 138.7 | T294: 152.6 | U294: 159.9 | V294: 154.8 | W294: 147.2 | X294: 156.9 | Y294: 141.7 | Z294: 148.6 | AA294: 157.6 | AB294: 154.9 | AC294: 150 | AD294: 156.9 | AF294: =(D295-D294)/D294*100 -> -2.3050847
A295: Rural+Urban | B295: 2021 | C295: March | D295: 144.1 | E295: 192.2 | F295: 163.8 | G295: 154.9 | H295: 163.9 | I295: 153.7 | J295: 149.5 | K295: 159.8 | L295: 112.6 | M295: 163.5 | N295: 156.5 | O295: 168.2 | P295: 156.7 | Q295: 188.1 | R295: 157.8 | S295: 147.9 | T295: 156.4 | U295: 159.9 | V295: 155.5 | W295: 151.2 | X295: 161.7 | Y295: 146.2 | Z295: 152.6 | AA295: 160.2 | AB295: 153.8 | AC295: 153.8 | AD295: 156.8 | AF295: =(D296-D295)/D295*100 -> -0.97154754
A296: Rural | B296: 2021 | C296: April | D296: 142.7 | E296: 195.5 | F296: 163.4 | G296: 155 | H296: 175.2 | I296: 160.6 | J296: 135.1 | K296: 161.1 | L296: 112.2 | M296: 164.4 | N296: 161.9 | O296: 166.8 | P296: 155.6 | Q296: 186.8 | R296: 160.7 | S296: 155.1 | T296: 159.9 | U296: - | V296: 156 | W296: 155.5 | X296: 165.3 | Y296: 151.7 | Z296: 158.6 | AA296: 164.1 | AB296: 154.6 | AC296: 158 | AD296: 157.6 | AF296: =(D297-D296)/D296*100 -> 3.4337772
A297: Urban | B297: 2021 | C297: April | D297: 147.6 | E297: 202.5 | F297: 166.4 | G297: 156 | H297: 161.4 | I297: 168.8 | J297: 161.6 | K297: 162.8 | L297: 114.8 | M297: 162.8 | N297: 151.5 | O297: 171.4 | P297: 162 | Q297: 194.4 | R297: 155.9 | S297: 139.3 | T297: 153.4 | U297: 161.4 | V297: 154.9 | W297: 147.6 | X297: 157.5 | Y297: 142.1 | Z297: 149.1 | AA297: 157.6 | AB297: 156.6 | AC297: 150.5 | AD297: 158 | AF297: =(D298-D297)/D297*100 -> -2.2357724
A298: Rural+Urban | B298: 2021 | C298: April | D298: 144.3 | E298: 198 | F298: 164.6 | G298: 155.4 | H298: 170.1 | I298: 164.4 | J298: 144.1 | K298: 161.7 | L298: 113.1 | M298: 163.9 | N298: 157.6 | O298: 168.9 | P298: 158 | Q298: 188.8 | R298: 158.8 | S298: 148.5 | T298: 157.3 | U298: 161.4 | V298: 155.6 | W298: 151.8 | X298: 162.3 | Y298: 146.6 | Z298: 153.2 | AA298: 160.3 | AB298: 155.4 | AC298: 154.4 | AD298: 157.8 | AF298: =(D299-D298)/D298*100 -> 0.55440055
A299: Rural | B299: 2021 | C299: May | D299: 145.1 | E299: 198.5 | F299: 168.6 | G299: 155.8 | H299: 184.4 | I299: 162.3 | J299: 138.4 | K299: 165.1 | L299: 114.3 | M299: 169.7 | N299: 164.6 | O299: 169.8 | P299: 158.7 | Q299: 189.6 | R299: 165.3 | S299: 160.6 | T299: 164.5 | U299: 0 | V299: 161.7 | W299: 158.8 | X299: 169.1 | Y299: 153.2 | Z299: 160 | AA299: 167.6 | AB299: 159.3 | AC299: 161.1 | AD299: 161.1 | AF299: =(D300-D299)/D299*100 -> 2.5499655
A300: Urban | B300: 2021 | C300: May | D300: 148.8 | E300: 204.3 | F300: 173 | G300: 156.5 | H300: 168.8 | I300: 172.5 | J300: 166.5 | K300: 165.9 | L300: 115.9 | M300: 165.2 | N300: 152 | O300: 171.1 | P300: 164.2 | Q300: 198.2 | R300: 156.5 | S300: 140.2 | T300: 154.1 | U300: 161.6 | V300: 155.5 | W300: 150.1 | X300: 160.4 | Y300: 145 | Z300: 152.6 | AA300: 156.6 | AB300: 157.5 | AC300: 152.3 | AD300: 159.5 | AF300: =(D301-D300)/D300*100 -> -1.6801075
A301: Rural+Urban | B301: 2021 | C301: May | D301: 146.3 | E301: 200.5 | F301: 170.3 | G301: 156.1 | H301: 178.7 | I301: 167.1 | J301: 147.9 | K301: 165.4 | L301: 114.8 | M301: 168.2 | N301: 159.3 | O301: 170.4 | P301: 160.7 | Q301: 191.9 | R301: 161.8 | S301: 152.1 | T301: 160.4 | U301: 161.6 | V301: 159.4 | W301: 154.7 | X301: 165.8 | Y301: 148.9 | Z301: 155.8 | AA301: 161.2 | AB301: 158.6 | AC301: 156.8 | AD301: 160.4 | AF301: =(D302-D301)/D301*100 -> -0.4784689
...

Sheet BROADER CATEGORIES
A1: Sector | B1: Year | C1: Month | D1: FOOD | E1: MEAT FISH AND EGG | F1: PAN TOBACCO AND INTOXICANTS | G1: WEARABLE | H1: HOUSING | I1: FUEL AND LIGHT | J1: HEALTH | K1: TRANSPORT AND COMMUNICATION | L1: OTHER | M1: TOTAL | N1: FOOD INFLATION | O1: MEAT FISH AND EGG INFLATION | P1: PAN TOBACCO AND INTOXICANTS INFLATION | Q1: WEARABLE INFLATION | R1: HOUSING INFLATION | S1: FUEL AND LIGHT INFLATION | T1: HEALTH INFLATION | U1: TRANSPORT INFLATION | V1: OTHERS INFLATION
A2: Rural | B2: 2013 | C2: January | D2: ='All_India_Index_Upto_April23 (1'!D2+'All_India_Index_Upto_April23 (1'!G2+'All_India_Index_Upto_April23 (1'!H2+'All_India_Index_Upto_April23 (1'!I2+'All_India_Index_Upto_April23 (1'!J2+'All_India_Index_Upto_April23 (1'!K2+'All_India_Index_Upto_April23 (1'!L2+'All_India_Index_Upto_April23 (1'!M2+'All_India_Index_Upto_April23 (1'!N2+'All_India_Index_Upto_April23 (1'!O2+'All_India_Index_Upto_April23 (1'!P2 -> 1157.3 | E2: ='All_India_Index_Upto_April23 (1'!E2+'All_India_Index_Upto_April23 (1'!F2 -> 214.4 | F2: 105.1 | G2: ='All_India_Index_Upto_April23 (1'!R2+'All_India_Index_Upto_April23 (1'!S2+'All_India_Index_Upto_April23 (1'!T2 -> 318.7 | H2: ='All_India_Index_Upto_April23 (1'!U2+'All_India_Index_Upto_April23 (1'!W2 -> 104.8 | I2: 105.5 | J2: 104 | K2: 103.3 | L2: ='All_India_Index_Upto_April23 (1'!Z2+'All_India_Index_Upto_April23 (1'!AA2+'All_India_Index_Upto_April23 (1'!AB2+'All_India_Index_Upto_April23 (1'!AC2+'All_India_Index_Upto_April23 (1'!AD2 -> 521 | M2: =D2+E2+F2+G2+H2+I2+J2+K2+L2 -> 2734.1 | N2: =D2/M2*100 -> 42.328371 | O2: =E2/M2*100 -> 7.8417029 | P2: =F2/M2*100 -> 3.8440437 | Q2: =G2/M2*100 -> 11.656487 | R2: =H2/M2*100 -> 3.8330712 | S2: =I2/M2*100 -> 3.8586738 | T2: =J2/M2*100 -> 3.8038111 | U2: =K2/M2*100 -> 3.7782086 | V2: =L2/M2*100 -> 19.055631 | W2: =N2+O2+P2+Q2+R2+S2+T2+U2+V2 -> 100
A3: Urban | B3: 2013 | C3: January | D3: ='All_India_Index_Upto_April23 (1'!D3+'All_India_Index_Upto_April23 (1'!G3+'All_India_Index_Upto_April23 (1'!H3+'All_India_Index_Upto_April23 (1'!I3+'All_India_Index_Upto_April23 (1'!J3+'All_India_Index_Upto_April23 (1'!K3+'All_India_Index_Upto_April23 (1'!L3+'All_India_Index_Upto_April23 (1'!M3+'All_India_Index_Upto_April23 (1'!N3+'All_India_Index_Upto_April23 (1'!O3+'All_India_Index_Upto_April23 (1'!P3 -> 1154.3 | E3: ='All_India_Index_Upto_April23 (1'!E3+'All_India_Index_Upto_April23 (1'!F3 -> 222.1 | F3: 105.2 | G3: ='All_India_Index_Upto_April23 (1'!R3+'All_India_Index_Upto_April23 (1'!S3+'All_India_Index_Upto_April23 (1'!T3 -> 316.7 | H3: ='All_India_Index_Upto_April23 (1'!U3+'All_India_Index_Upto_April23 (1'!W3 -> 205.1 | I3: 105.4 | J3: 104.1 | K3: 103.2 | L3: ='All_India_Index_Upto_April23 (1'!Z3+'All_India_Index_Upto_April23 (1'!AA3+'All_India_Index_Upto_April23 (1'!AB3+'All_India_Index_Upto_April23 (1'!AC3+'All_India_Index_Upto_April23 (1'!AD3 -> 518.4 | M3: =D3+E3+F3+G3+H3+I3+J3+K3+L3 -> 2834.5 | N3: =D3/M3*100 -> 40.723232 | O3: =E3/M3*100 -> 7.8355971 | P3: =F3/M3*100 -> 3.7114129 | Q3: =G3/M3*100 -> 11.173046 | R3: =H3/M3*100 -> 7.2358441 | S3: =I3/M3*100 -> 3.7184689 | T3: =J3/M3*100 -> 3.6726054 | U3: =K3/M3*100 -> 3.6408538 | V3: =L3/M3*100 -> 18.28894 | W3: =N3+O3+P3+Q3+R3+S3+T3+U3+V3 -> 100
A4: Rural+Urban | B4: 2013 | C4: January | D4: ='All_India_Index_Upto_April23 (1'!D4+'All_India_Index_Upto_April23 (1'!G4+'All_India_Index_Upto_April23 (1'!H4+'All_India_Index_Upto_April23 (1'!I4+'All_India_Index_Upto_April23 (1'!J4+'All_India_Index_Upto_April23 (1'!K4+'All_India_Index_Upto_April23 (1'!L4+'All_India_Index_Upto_April23 (1'!M4+'All_India_Index_Upto_April23 (1'!N4+'All_India_Index_Upto_April23 (1'!O4+'All_India_Index_Upto_April23 (1'!P4 -> 1156 | E4: ='All_India_Index_Upto_April23 (1'!E4+'All_India_Index_Upto_April23 (1'!F4 -> 217.3 | F4: 105.1 | G4: ='All_India_Index_Upto_April23 (1'!R4+'All_India_Index_Upto_April23 (1'!S4+'All_India_Index_Upto_April23 (1'!T4 -> 318 | H4: ='All_India_Index_Upto_April23 (1'!U4+'All_India_Index_Upto_April23 (1'!W4 -> 205.1 | I4: 105.5 | J4: 104 | K4: 103.2 | L4: ='All_India_Index_Upto_April23 (1'!Z4+'All_India_Index_Upto_April23 (1'!AA4+'All_India_Index_Upto_April23 (1'!AB4+'All_India_Index_Upto_April23 (1'!AC4+'All_India_Index_Upto_April23 (1'!AD4 -> 519.7 | M4: =D4+E4+F4+G4+H4+I4+J4+K4+L4 -> 2833.9 | N4: =D4/M4*100 -> 40.791842 | O4: =E4/M4*100 -> 7.6678782 | P4: =F4/M4*100 -> 3.70867 | Q4: =G4/M4*100 -> 11.221285 | R4: =H4/M4*100 -> 7.2373761 | S4: =I4/M4*100 -> 3.7227849 | T4: =J4/M4*100 -> 3.6698543 | U4: =K4/M4*100 -> 3.6416246 | V4: =L4/M4*100 -> 18.338685 | W4: =N4+O4+P4+Q4+R4+S4+T4+U4+V4 -> 100
A5: Rural | B5: 2013 | C5: February | D5: ='All_India_Index_Upto_April23 (1'!D5+'All_India_Index_Upto_April23 (1'!G5+'All_India_Index_Upto_April23 (1'!H5+'All_India_Index_Upto_April23 (1'!I5+'All_India_Index_Upto_April23 (1'!J5+'All_India_Index_Upto_April23 (1'!K5+'All_India_Index_Upto_April23 (1'!L5+'All_India_Index_Upto_April23 (1'!M5+'All_India_Index_Upto_April23 (1'!N5+'All_India_Index_Upto_April23 (1'!O5+'All_India_Index_Upto_April23 (1'!P5 -> 1161.5 | E5: ='All_India_Index_Upto_April23 (1'!E5+'All_India_Index_Upto_April23 (1'!F5 -> 218.9 | F5: 105.6 | G5: ='All_India_Index_Upto_April23 (1'!R5+'All_India_Index_Upto_April23 (1'!S5+'All_India_Index_Upto_April23 (1'!T5 -> 320.4 | H5: ='All_India_Index_Upto_April23 (1'!U5+'All_India_Index_Upto_April23 (1'!W5 -> 105.2 | I5: 106.2 | J5: 104.4 | K5: 103.9 | L5: ='All_India_Index_Upto_April23 (1'!Z5+'All_India_Index_Upto_April23 (1'!AA5+'All_India_Index_Upto_April23 (1'!AB5+'All_India_Index_Upto_April23 (1'!AC5+'All_India_Index_Upto_April23 (1'!AD5 -> 522.9 | M5: =D5+E5+F5+G5+H5+I5+J5+K5+L5 -> 2749 | N5: =D5/M5*100 -> 42.251728 | O5: =E5/M5*100 -> 7.9628956 | P5: =F5/M5*100 -> 3.8413969 | Q5: =G5/M5*100 -> 11.655147 | R5: =H5/M5*100 -> 3.8268461 | S5: =I5/M5*100 -> 3.863223 | T5: =J5/M5*100 -> 3.7977446 | U5: =K5/M5*100 -> 3.7795562 | V5: =L5/M5*100 -> 19.021462 | W5: =N5+O5+P5+Q5+R5+S5+T5+U5+V5 -> 100
A6: Urban | B6: 2013 | C6: February | D6: ='All_India_Index_Upto_April23 (1'!D6+'All_India_Index_Upto_April23 (1'!G6+'All_India_Index_Upto_April23 (1'!H6+'All_India_Index_Upto_April23 (1'!I6+'All_India_Index_Upto_April23 (1'!J6+'All_India_Index_Upto_April23 (1'!K6+'All_India_Index_Upto_April23 (1'!L6+'All_India_Index_Upto_April23 (1'!M6+'All_India_Index_Upto_April23 (1'!N6+'All_India_Index_Upto_April23 (1'!O6+'All_India_Index_Upto_April23 (1'!P6 -> 1160.8 | E6: ='All_India_Index_Upto_April23 (1'!E6+'All_India_Index_Upto_April23 (1'!F6 -> 229.8 | F6: 106 | G6: ='All_India_Index_Upto_April23 (1'!R6+'All_India_Index_Upto_April23 (1'!S6+'All_India_Index_Upto_April23 (1'!T6 -> 318.5 | H6: ='All_India_Index_Upto_April23 (1'!U6+'All_India_Index_Upto_April23 (1'!W6 -> 205.6 | I6: 105.7 | J6: 104.7 | K6: 104.4 | L6: ='All_India_Index_Upto_April23 (1'!Z6+'All_India_Index_Upto_April23 (1'!AA6+'All_India_Index_Upto_April23 (1'!AB6+'All_India_Index_Upto_April23 (1'!AC6+'All_India_Index_Upto_April23 (1'!AD6 -> 520.3 | M6: =D6+E6+F6+G6+H6+I6+J6+K6+L6 -> 2855.8 | N6: =D6/M6*100 -> 40.647104 | O6: =E6/M6*100 -> 8.046782 | P6: =F6/M6*100 -> 3.7117445 | Q6: =G6/M6*100 -> 11.152742 | R6: =H6/M6*100 -> 7.1993837 | S6: =I6/M6*100 -> 3.7012396 | T6: =J6/M6*100 -> 3.6662231 | U6: =K6/M6*100 -> 3.6557182 | V6: =L6/M6*100 -> 18.219063 | W6: =N6+O6+P6+Q6+R6+S6+T6+U6+V6 -> 100
A7: Rural+Urban | B7: 2013 | C7: February | D7: ='All_India_Index_Upto_April23 (1'!D7+'All_India_Index_Upto_April23 (1'!G7+'All_India_Index_Upto_April23 (1'!H7+'All_India_Index_Upto_April23 (1'!I7+'All_India_Index_Upto_April23 (1'!J7+'All_India_Index_Upto_April23 (1'!K7+'All_India_Index_Upto_April23 (1'!L7+'All_India_Index_Upto_April23 (1'!M7+'All_India_Index_Upto_April23 (1'!N7+'All_India_Index_Upto_April23 (1'!O7+'All_India_Index_Upto_April23 (1'!P7 -> 1161.2 | E7: ='All_India_Index_Upto_April23 (1'!E7+'All_India_Index_Upto_April23 (1'!F7 -> 223 | F7: 105.7 | G7: ='All_India_Index_Upto_April23 (1'!R7+'All_India_Index_Upto_April23 (1'!S7+'All_India_Index_Upto_April23 (1'!T7 -> 319.7 | H7: ='All_India_Index_Upto_April23 (1'!U7+'All_India_Index_Upto_April23 (1'!W7 -> 205.6 | I7: 106 | J7: 104.5 | K7: 104.2 | L7: ='All_India_Index_Upto_April23 (1'!Z7+'All_India_Index_Upto_April23 (1'!AA7+'All_India_Index_Upto_April23 (1'!AB7+'All_India_Index_Upto_April23 (1'!AC7+'All_India_Index_Upto_April23 (1'!AD7 -> 521.7 | M7: =D7+E7+F7+G7+H7+I7+J7+K7+L7 -> 2851.6 | N7: =D7/M7*100 -> 40.720999 | O7: =E7/M7*100 -> 7.8201711 | P7: =F7/M7*100 -> 3.706691 | Q7: =G7/M7*100 -> 11.21125 | R7: =H7/M7*100 -> 7.2099874 | S7: =I7/M7*100 -> 3.7172114 | T7: =J7/M7*100 -> 3.6646093 | U7: =K7/M7*100 -> 3.6540889 | V7: =L7/M7*100 -> 18.294992 | W7: =N7+O7+P7+Q7+R7+S7+T7+U7+V7 -> 100
A8: Rural | B8: 2013 | C8: March | D8: ='All_India_Index_Upto_April23 (1'!D8+'All_India_Index_Upto_April23 (1'!G8+'All_India_Index_Upto_April23 (1'!H8+'All_India_Index_Upto_April23 (1'!I8+'All_India_Index_Upto_April23 (1'!J8+'All_India_Index_Upto_April23 (1'!K8+'All_India_Index_Upto_April23 (1'!L8+'All_India_Index_Upto_April23 (1'!M8+'All_India_Index_Upto_April23 (1'!N8+'All_India_Index_Upto_April23 (1'!O8+'All_India_Index_Upto_April23 (1'!P8 -> 1163.5 | E8: ='All_India_Index_Upto_April23 (1'!E8+'All_India_Index_Upto_April23 (1'!F8 -> 218.7 | F8: 106.5 | G8: ='All_India_Index_Upto_April23 (1'!R8+'All_India_Index_Upto_April23 (1'!S8+'All_India_Index_Upto_April23 (1'!T8 -> 321.9 | H8: ='All_India_Index_Upto_April23 (1'!U8+'All_India_Index_Upto_April23 (1'!W8 -> 105.6 | I8: 106.1 | J8: 104.7 | K8: 104.6 | L8: ='All_India_Index_Upto_April23 (1'!Z8+'All_India_Index_Upto_April23 (1'!AA8+'All_India_Index_Upto_April23 (1'!AB8+'All_India_Index_Upto_April23 (1'!AC8+'All_India_Index_Upto_April23 (1'!AD8 -> 523.2 | M8: =D8+E8+F8+G8+H8+I8+J8+K8+L8 -> 2754.8 | N8: =D8/M8*100 -> 42.235371 | O8: =E8/M8*100 -> 7.9388703 | P8: =F8/M8*100 -> 3.8659794 | Q8: =G8/M8*100 -> 11.685059 | R8: =H8/M8*100 -> 3.8333091 | S8: =I8/M8*100 -> 3.8514593 | T8: =J8/M8*100 -> 3.8006389 | U8: =K8/M8*100 -> 3.7970089 | V8: =L8/M8*100 -> 18.992304 | W8: =N8+O8+P8+Q8+R8+S8+T8+U8+V8 -> 100
A9: Urban | B9: 2013 | C9: March | D9: ='All_India_Index_Upto_April23 (1'!D9+'All_India_Index_Upto_April23 (1'!G9+'All_India_Index_Upto_April23 (1'!H9+'All_India_Index_Upto_April23 (1'!I9+'All_India_Index_Upto_April23 (1'!J9+'All_India_Index_Upto_April23 (1'!K9+'All_India_Index_Upto_April23 (1'!L9+'All_India_Index_Upto_April23 (1'!M9+'All_India_Index_Upto_April23 (1'!N9+'All_India_Index_Upto_April23 (1'!O9+'All_India_Index_Upto_April23 (1'!P9 -> 1162.2 | E9: ='All_India_Index_Upto_April23 (1'!E9+'All_India_Index_Upto_April23 (1'!F9 -> 224.6 | F9: 106.8 | G9: ='All_India_Index_Upto_April23 (1'!R9+'All_India_Index_Upto_April23 (1'!S9+'All_India_Index_Upto_April23 (1'!T9 -> 320.2 | H9: ='All_India_Index_Upto_April23 (1'!U9+'All_India_Index_Upto_April23 (1'!W9 -> 206.1 | I9: 106 | J9: 105.2 | K9: 105.5 | L9: ='All_India_Index_Upto_April23 (1'!Z9+'All_India_Index_Upto_April23 (1'!AA9+'All_India_Index_Upto_April23 (1'!AB9+'All_India_Index_Upto_April23 (1'!AC9+'All_India_Index_Upto_April23 (1'!AD9 -> 521.4 | M9: =D9+E9+F9+G9+H9+I9+J9+K9+L9 -> 2858 | N9: =D9/M9*100 -> 40.664801 | O9: =E9/M9*100 -> 7.8586424 | P9: =F9/M9*100 -> 3.7368789 | Q9: =G9/M9*100 -> 11.203639 | R9: =H9/M9*100 -> 7.2113366 | S9: =I9/M9*100 -> 3.7088873 | T9: =J9/M9*100 -> 3.6808957 | U9: =K9/M9*100 -> 3.6913926 | V9: =L9/M9*100 -> 18.243527 | W9: =N9+O9+P9+Q9+R9+S9+T9+U9+V9 -> 100
A10: Rural+Urban | B10: 2013 | C10: March | D10: ='All_India_Index_Upto_April23 (1'!D10+'All_India_Index_Upto_April23 (1'!G10+'All_India_Index_Upto_April23 (1'!H10+'All_India_Index_Upto_April23 (1'!I10+'All_India_Index_Upto_April23 (1'!J10+'All_India_Index_Upto_April23 (1'!K10+'All_India_Index_Upto_April23 (1'!L10+'All_India_Index_Upto_April23 (1'!M10+'All_India_Index_Upto_April23 (1'!N10+'All_India_Index_Upto_April23 (1'!O10+'All_India_Index_Upto_April23 (1'!P10 -> 1163.1 | E10: ='All_India_Index_Upto_April23 (1'!E10+'All_India_Index_Upto_April23 (1'!F10 -> 220.9 | F10: 106.6 | G10: ='All_India_Index_Upto_April23 (1'!R10+'All_India_Index_Upto_April23 (1'!S10+'All_India_Index_Upto_April23 (1'!T10 -> 321.2 | H10: ='All_India_Index_Upto_April23 (1'!U10+'All_India_Index_Upto_April23 (1'!W10 -> 206 | I10: 106.1 | J10: 104.9 | K10: 105.1 | L10: ='All_India_Index_Upto_April23 (1'!Z10+'All_India_Index_Upto_April23 (1'!AA10+'All_India_Index_Upto_April23 (1'!AB10+'All_India_Index_Upto_April23 (1'!AC10+'All_India_Index_Upto_April23 (1'!AD10 -> 522.2 | M10: =D10+E10+F10+G10+H10+I10+J10+K10+L10 -> 2856.1 | N10: =D10/M10*100 -> 40.723364 | O10: =E10/M10*100 -> 7.734323 | P10: =F10/M10*100 -> 3.7323623 | Q10: =G10/M10*100 -> 11.246105 | R10: =H10/M10*100 -> 7.2126326 | S10: =I10/M10*100 -> 3.7148559 | T10: =J10/M10*100 -> 3.6728406 | U10: =K10/M10*100 -> 3.6798431 | V10: =L10/M10*100 -> 18.283674 | W10: =N10+O10+P10+Q10+R10+S10+T10+U10+V10 -> 100
A11: Rural | B11: 2013 | C11: April | D11: ='All_India_Index_Upto_April23 (1'!D11+'All_India_Index_Upto_April23 (1'!G11+'All_India_Index_Upto_April23 (1'!H11+'All_India_Index_Upto_April23 (1'!I11+'All_India_Index_Upto_April23 (1'!J11+'All_India_Index_Upto_April23 (1'!K11+'All_India_Index_Upto_April23 (1'!L11+'All_India_Index_Upto_April23 (1'!M11+'All_India_Index_Upto_April23 (1'!N11+'All_India_Index_Upto_April23 (1'!O11+'All_India_Index_Upto_April23 (1'!P11 -> 1169.4 | E11: ='All_India_Index_Upto_April23 (1'!E11+'All_India_Index_Upto_April23 (1'!F11 -> 216.4 | F11: 107.1 | G11: ='All_India_Index_Upto_April23 (1'!R11+'All_India_Index_Upto_April23 (1'!S11+'All_India_Index_Upto_April23 (1'!T11 -> 323.5 | H11: ='All_India_Index_Upto_April23 (1'!U11+'All_India_Index_Upto_April23 (1'!W11 -> 106.1 | I11: 106.5 | J11: 105.1 | K11: 104.4 | L11: ='All_India_Index_Upto_April23 (1'!Z11+'All_India_Index_Upto_April23 (1'!AA11+'All_India_Index_Upto_April23 (1'!AB11+'All_India_Index_Upto_April23 (1'!AC11+'All_India_Index_Upto_April23 (1'!AD11 -> 523 | M11: =D11+E11+F11+G11+H11+I11+J11+K11+L11 -> 2761.5 | N11: =D11/M11*100 -> 42.346551 | O11: =E11/M11*100 -> 7.8363208 | P11: =F11/M11*100 -> 3.878327 | Q11: =G11/M11*100 -> 11.714648 | R11: =H11/M11*100 -> 3.8421148 | S11: =I11/M11*100 -> 3.8565997 | T11: =J11/M11*100 -> 3.8059026 | U11: =K11/M11*100 -> 3.780554 | V11: =L11/M11*100 -> 18.938982 | W11: =N11+O11+P11+Q11+R11+S11+T11+U11+V11 -> 100
A12: Urban | B12: 2013 | C12: April | D12: ='All_India_Index_Upto_April23 (1'!D12+'All_India_Index_Upto_April23 (1'!G12+'All_India_Index_Upto_April23 (1'!H12+'All_India_Index_Upto_April23 (1'!I12+'All_India_Index_Upto_April23 (1'!J12+'All_India_Index_Upto_April23 (1'!K12+'All_India_Index_Upto_April23 (1'!L12+'All_India_Index_Upto_April23 (1'!M12+'All_India_Index_Upto_April23 (1'!N12+'All_India_Index_Upto_April23 (1'!O12+'All_India_Index_Upto_April23 (1'!P12 -> 1178.3 | E12: ='All_India_Index_Upto_April23 (1'!E12+'All_India_Index_Upto_April23 (1'!F12 -> 219.4 | F12: 108.5 | G12: ='All_India_Index_Upto_April23 (1'!R12+'All_India_Index_Upto_April23 (1'!S12+'All_India_Index_Upto_April23 (1'!T12 -> 322 | H12: ='All_India_Index_Upto_April23 (1'!U12+'All_India_Index_Upto_April23 (1'!W12 -> 207 | I12: 106.4 | J12: 105.7 | K12: 105 | L12: ='All_India_Index_Upto_April23 (1'!Z12+'All_India_Index_Upto_April23 (1'!AA12+'All_India_Index_Upto_April23 (1'!AB12+'All_India_Index_Upto_April23 (1'!AC12+'All_India_Index_Upto_April23 (1'!AD12 -> 523.2 | M12: =D12+E12+F12+G12+H12+I12+J12+K12+L12 -> 2875.5 | N12: =D12/M12*100 -> 40.977221 | O12: =E12/M12*100 -> 7.6299774 | P12: =F12/M12*100 -> 3.7732568 | Q12: =G12/M12*100 -> 11.198053 | R12: =H12/M12*100 -> 7.198748 | S12: =I12/M12*100 -> 3.700226 | T12: =J12/M12*100 -> 3.6758825 | U12: =K12/M12*100 -> 3.6515389 | V12: =L12/M12*100 -> 18.195097 | W12: =N12+O12+P12+Q12+R12+S12+T12+U12+V12 -> 100
A13: Rural+Urban | B13: 2013 | C13: April | D13: ='All_India_Index_Upto_April23 (1'!D13+'All_India_Index_Upto_April23 (1'!G13+'All_India_Index_Upto_April23 (1'!H13+'All_India_Index_Upto_April23 (1'!I13+'All_India_Index_Upto_April23 (1'!J13+'All_India_Index_Upto_April23 (1'!K13+'All_India_Index_Upto_April23 (1'!L13+'All_India_Index_Upto_April23 (1'!M13+'All_India_Index_Upto_April23 (1'!N13+'All_India_Index_Upto_April23 (1'!O13+'All_India_Index_Upto_April23 (1'!P13 -> 1172.7 | E13: ='All_India_Index_Upto_April23 (1'!E13+'All_India_Index_Upto_April23 (1'!F13 -> 217.5 | F13: 107.5 | G13: ='All_India_Index_Upto_April23 (1'!R13+'All_India_Index_Upto_April23 (1'!S13+'All_India_Index_Upto_April23 (1'!T13 -> 322.9 | H13: ='All_India_Index_Upto_April23 (1'!U13+'All_India_Index_Upto_April23 (1'!W13 -> 206.8 | I13: 106.5 | J13: 105.3 | K13: 104.7 | L13: ='All_India_Index_Upto_April23 (1'!Z13+'All_India_Index_Upto_April23 (1'!AA13+'All_India_Index_Upto_April23 (1'!AB13+'All_India_Index_Upto_April23 (1'!AC13+'All_India_Index_Upto_April23 (1'!AD13 -> 523 | M13: =D13+E13+F13+G13+H13+I13+J13+K13+L13 -> 2866.9 | N13: =D13/M13*100 -> 40.90481 | O13: =E13/M13*100 -> 7.5865918 | P13: =F13/M13*100 -> 3.7496948 | Q13: =G13/M13*100 -> 11.263037 | R13: =H13/M13*100 -> 7.2133664 | S13: =I13/M13*100 -> 3.7148139 | T13: =J13/M13*100 -> 3.6729569 | U13: =K13/M13*100 -> 3.6520283 | V13: =L13/M13*100 -> 18.242701 | W13: =N13+O13+P13+Q13+R13+S13+T13+U13+V13 -> 100
... A264: Urban | B264: 2020 | C264: May | D264: ='All_India_Index_Upto_April23 (1'!D264+'All_India_Index_Upto_April23 (1'!G264+'All_India_Index_Upto_April23 (1'!H264+'All_India_Index_Upto_April23 (1'!I264+'All_India_Index_Upto_April23 (1'!J264+'All_India_Index_Upto_April23 (1'!K264+'All_India_Index_Upto_April23 (1'!L264+'All_India_Index_Upto_April23 (1'!M264+'All_India_Index_Upto_April23 (1'!N264+'All_India_Index_Upto_April23 (1'!O264+'All_India_Index_Upto_April23 (1'!P264 -> 1602.8 | E264: ='All_India_Index_Upto_April23 (1'!E264+'All_India_Index_Upto_April23 (1'!F264 -> 318.4 | F264: 170.7 | G264: ='All_India_Index_Upto_April23 (1'!R264+'All_India_Index_Upto_April23 (1'!S264+'All_India_Index_Upto_April23 (1'!T264 -> 438.9 | H264: ='All_India_Index_Upto_April23 (1'!U264+'All_India_Index_Upto_April23 (1'!W264 -> 253.7 | I264: 144.7 | J264: 150 | K264: 130 | L264: ='All_India_Index_Upto_April23 (1'!Z264+'All_India_Index_Upto_April23 (1'!AA264+'All_India_Index_Upto_April23 (1'!AB264+'All_India_Index_Upto_April23 (1'!AC264+'All_India_Index_Upto_April23 (1'!AD264 -> 734.8 | M264: =D264+E264+F264+G264+H264+I264+J264+K264+L264 -> 3944 | N264: =D264/M264*100 -> 40.638945 | O264: =E264/M264*100 -> 8.0730223 | P264: =F264/M264*100 -> 4.3280933 | Q264: =G264/M264*100 -> 11.128296 | R264: =H264/M264*100 -> 6.4325558 | S264: =I264/M264*100 -> 3.6688641 | T264: =J264/M264*100 -> 3.8032454 | U264: =K264/M264*100 -> 3.296146 | V264: =L264/M264*100 -> 18.630832 | W264: =N264+O264+P264+Q264+R264+S264+T264+U264+V264 -> 100
A265: Rural+Urban | B265: 2020 | C265: May | D265: ='All_India_Index_Upto_April23 (1'!D265+'All_India_Index_Upto_April23 (1'!G265+'All_India_Index_Upto_April23 (1'!H265+'All_India_Index_Upto_April23 (1'!I265+'All_India_Index_Upto_April23 (1'!J265+'All_India_Index_Upto_April23 (1'!K265+'All_India_Index_Upto_April23 (1'!L265+'All_India_Index_Upto_April23 (1'!M265+'All_India_Index_Upto_April23 (1'!N265+'All_India_Index_Upto_April23 (1'!O265+'All_India_Index_Upto_April23 (1'!P265 -> 1603.6567 | E265: ='All_India_Index_Upto_April23 (1'!E265+'All_India_Index_Upto_April23 (1'!F265 -> 317.5 | F265: 170.7 | G265: ='All_India_Index_Upto_April23 (1'!R265+'All_India_Index_Upto_April23 (1'!S265+'All_India_Index_Upto_April23 (1'!T265 -> 440.7 | H265: ='All_India_Index_Upto_April23 (1'!U265+'All_India_Index_Upto_April23 (1'!W265 -> 254.57 | I265: 145.6 | J265: 150.7 | K265: =AVERAGE(K253:K262) -> 130.43 | L265: ='All_India_Index_Upto_April23 (1'!Z265+'All_India_Index_Upto_April23 (1'!AA265+'All_India_Index_Upto_April23 (1'!AB265+'All_India_Index_Upto_April23 (1'!AC265+'All_India_Index_Upto_April23 (1'!AD265 -> 737 | M265: =D265+E265+F265+G265+H265+I265+J265+K265+L265 -> 3950.8567 | N265: =D265/M265*100 -> 40.5901 | O265: =E265/M265*100 -> 8.0362318 | P265: =F265/M265*100 -> 4.3205819 | Q265: =G265/M265*100 -> 11.154543 | R265: =H265/M265*100 -> 6.4434127 | S265: =I265/M265*100 -> 3.6852767 | T265: =J265/M265*100 -> 3.8143626 | U265: =K265/M265*100 -> 3.3013093 | V265: =L265/M265*100 -> 18.654182 | W265: =N265+O265+P265+Q265+R265+S265+T265+U265+V265 -> 100
A266: Rural | B266: 2020 | C266: June | D266: ='All_India_Index_Upto_April23 (1'!D266+'All_India_Index_Upto_April23 (1'!G266+'All_India_Index_Upto_April23 (1'!H266+'All_India_Index_Upto_April23 (1'!I266+'All_India_Index_Upto_April23 (1'!J266+'All_India_Index_Upto_April23 (1'!K266+'All_India_Index_Upto_April23 (1'!L266+'All_India_Index_Upto_April23 (1'!M266+'All_India_Index_Upto_April23 (1'!N266+'All_India_Index_Upto_April23 (1'!O266+'All_India_Index_Upto_April23 (1'!P266 -> 1611.3 | E266: ='All_India_Index_Upto_April23 (1'!E266+'All_India_Index_Upto_April23 (1'!F266 -> 339.7 | F266: 182.4 | G266: ='All_India_Index_Upto_April23 (1'!R266+'All_India_Index_Upto_April23 (1'!S266+'All_India_Index_Upto_April23 (1'!T266 -> 458.8 | H266: ='All_India_Index_Upto_April23 (1'!U266+'All_India_Index_Upto_April23 (1'!W266 -> 151.7 | I266: 144.9 | J266: 158.2 | K266: 141.4 | L266: ='All_India_Index_Upto_April23 (1'!Z266+'All_India_Index_Upto_April23 (1'!AA266+'All_India_Index_Upto_April23 (1'!AB266+'All_India_Index_Upto_April23 (1'!AC266+'All_India_Index_Upto_April23 (1'!AD266 -> 770.6 | M266: =D266+E266+F266+G266+H266+I266+J266+K266+L266 -> 3959 | N266: =D266/M266*100 -> 40.699672 | O266: =E266/M266*100 -> 8.5804496 | P266: =F266/M266*100 -> 4.607224 | Q266: =G266/M266*100 -> 11.588785 | R266: =H266/M266*100 -> 3.8317757 | S266: =I266/M266*100 -> 3.6600152 | T266: =J266/M266*100 -> 3.9959586 | U266: =K266/M266*100 -> 3.571609 | V266: =L266/M266*100 -> 19.464511 | W266: =N266+O266+P266+Q266+R266+S266+T266+U266+V266 -> 100
A267: Urban | B267: 2020 | C267: June | D267: ='All_India_Index_Upto_April23 (1'!D267+'All_India_Index_Upto_April23 (1'!G267+'All_India_Index_Upto_April23 (1'!H267+'All_India_Index_Upto_April23 (1'!I267+'All_India_Index_Upto_April23 (1'!J267+'All_India_Index_Upto_April23 (1'!K267+'All_India_Index_Upto_April23 (1'!L267+'All_India_Index_Upto_April23 (1'!M267+'All_India_Index_Upto_April23 (1'!N267+'All_India_Index_Upto_April23 (1'!O267+'All_India_Index_Upto_April23 (1'!P267 -> 1643.4 | E267: ='All_India_Index_Upto_April23 (1'!E267+'All_India_Index_Upto_April23 (1'!F267 -> 351.6 | F267: 186.7 | G267: ='All_India_Index_Upto_April23 (1'!R267+'All_India_Index_Upto_April23 (1'!S267+'All_India_Index_Upto_April23 (1'!T267 -> 432.9 | H267: ='All_India_Index_Upto_April23 (1'!U267+'All_India_Index_Upto_April23 (1'!W267 -> 295.1 | I267: 137.1 | J267: 148.1 | K267: 129.3 | L267: ='All_India_Index_Upto_April23 (1'!Z267+'All_India_Index_Upto_April23 (1'!AA267+'All_India_Index_Upto_April23 (1'!AB267+'All_India_Index_Upto_April23 (1'!AC267+'All_India_Index_Upto_April23 (1'!AD267 -> 742 | M267: =D267+E267+F267+G267+H267+I267+J267+K267+L267 -> 4066.2 | N267: =D267/M267*100 -> 40.416113 | O267: =E267/M267*100 -> 8.6468939 | P267: =F267/M267*100 -> 4.5915105 | Q267: =G267/M267*100 -> 10.646304 | R267: =H267/M267*100 -> 7.2573902 | S267: =I267/M267*100 -> 3.3716984 | T267: =J267/M267*100 -> 3.6422212 | U267: =K267/M267*100 -> 3.1798731 | V267: =L267/M267*100 -> 18.247996 | W267: =N267+O267+P267+Q267+R267+S267+T267+U267+V267 -> 100
A268: Rural+Urban | B268: 2020 | C268: June | D268: ='All_India_Index_Upto_April23 (1'!D268+'All_India_Index_Upto_April23 (1'!G268+'All_India_Index_Upto_April23 (1'!H268+'All_India_Index_Upto_April23 (1'!I268+'All_India_Index_Upto_April23 (1'!J268+'All_India_Index_Upto_April23 (1'!K268+'All_India_Index_Upto_April23 (1'!L268+'All_India_Index_Upto_April23 (1'!M268+'All_India_Index_Upto_April23 (1'!N268+'All_India_Index_Upto_April23 (1'!O268+'All_India_Index_Upto_April23 (1'!P268 -> 1622.7 | E268: ='All_India_Index_Upto_April23 (1'!E268+'All_India_Index_Upto_April23 (1'!F268 -> 344.1 | F268: 183.5 | G268: ='All_India_Index_Upto_April23 (1'!R268+'All_India_Index_Upto_April23 (1'!S268+'All_India_Index_Upto_April23 (1'!T268 -> 448.3 | H268: ='All_India_Index_Upto_April23 (1'!U268+'All_India_Index_Upto_April23 (1'!W268 -> 301.1 | I268: 141.9 | J268: 154.4 | K268: 135 | L268: ='All_India_Index_Upto_April23 (1'!Z268+'All_India_Index_Upto_April23 (1'!AA268+'All_India_Index_Upto_April23 (1'!AB268+'All_India_Index_Upto_April23 (1'!AC268+'All_India_Index_Upto_April23 (1'!AD268 -> 755.1 | M268: =D268+E268+F268+G268+H268+I268+J268+K268+L268 -> 4086.1 | N268: =D268/M268*100 -> 39.712684 | O268: =E268/M268*100 -> 8.421233 | P268: =F268/M268*100 -> 4.4908348 | Q268: =G268/M268*100 -> 10.971342 | R268: =H268/M268*100 -> 7.3688848 | S268: =I268/M268*100 -> 3.4727491 | T268: =J268/M268*100 -> 3.7786643 | U268: =K268/M268*100 -> 3.3038839 | V268: =L268/M268*100 -> 18.479724 | W268: =N268+O268+P268+Q268+R268+S268+T268+U268+V268 -> 100
A269: Rural | B269: 2020 | C269: July | D269: ='All_India_Index_Upto_April23 (1'!D269+'All_India_Index_Upto_April23 (1'!G269+'All_India_Index_Upto_April23 (1'!H269+'All_India_Index_Upto_April23 (1'!I269+'All_India_Index_Upto_April23 (1'!J269+'All_India_Index_Upto_April23 (1'!K269+'All_India_Index_Upto_April23 (1'!L269+'All_India_Index_Upto_April23 (1'!M269+'All_India_Index_Upto_April23 (1'!N269+'All_India_Index_Upto_April23 (1'!O269+'All_India_Index_Upto_April23 (1'!P269 -> 1611.3 | E269: ='All_India_Index_Upto_April23 (1'!E269+'All_India_Index_Upto_April23 (1'!F269 -> 339.7 | F269: 182.4 | G269: ='All_India_Index_Upto_April23 (1'!R269+'All_India_Index_Upto_April23 (1'!S269+'All_India_Index_Upto_April23 (1'!T269 -> 458.8 | H269: ='All_India_Index_Upto_April23 (1'!U269+'All_India_Index_Upto_April23 (1'!W269 -> 151.7 | I269: 144.9 | J269: 158.2 | K269: 141.4 | L269: ='All_India_Index_Upto_April23 (1'!Z269+'All_India_Index_Upto_April23 (1'!AA269+'All_India_Index_Upto_April23 (1'!AB269+'All_India_Index_Upto_April23 (1'!AC269+'All_India_Index_Upto_April23 (1'!AD269 -> 770.6 | M269: =D269+E269+F269+G269+H269+I269+J269+K269+L269 -> 3959 | N269: =D269/M269*100 -> 40.699672 | O269: =E269/M269*100 -> 8.5804496 | P269: =F269/M269*100 -> 4.607224 | Q269: =G269/M269*100 -> 11.588785 | R269: =H269/M269*100 -> 3.8317757 | S269: =I269/M269*100 -> 3.6600152 | T269: =J269/M269*100 -> 3.9959586 | U269: =K269/M269*100 -> 3.571609 | V269: =L269/M269*100 -> 19.464511 | W269: =N269+O269+P269+Q269+R269+S269+T269+U269+V269 -> 100
A270: Urban | B270: 2020 | C270: July | D270: ='All_India_Index_Upto_April23 (1'!D270+'All_India_Index_Upto_April23 (1'!G270+'All_India_Index_Upto_April23 (1'!H270+'All_India_Index_Upto_April23 (1'!I270+'All_India_Index_Upto_April23 (1'!J270+'All_India_Index_Upto_April23 (1'!K270+'All_India_Index_Upto_April23 (1'!L270+'All_India_Index_Upto_April23 (1'!M270+'All_India_Index_Upto_April23 (1'!N270+'All_India_Index_Upto_April23 (1'!O270+'All_India_Index_Upto_April23 (1'!P270 -> 1643.4 | E270: ='All_India_Index_Upto_April23 (1'!E270+'All_India_Index_Upto_April23 (1'!F270 -> 351.6 | F270: 186.7 | G270: ='All_India_Index_Upto_April23 (1'!R270+'All_India_Index_Upto_April23 (1'!S270+'All_India_Index_Upto_April23 (1'!T270 -> 432.9 | H270: ='All_India_Index_Upto_April23 (1'!U270+'All_India_Index_Upto_April23 (1'!W270 -> 295.1 | I270: 137.1 | J270: 148.1 | K270: 129.3 | L270: ='All_India_Index_Upto_April23 (1'!Z270+'All_India_Index_Upto_April23 (1'!AA270+'All_India_Index_Upto_April23 (1'!AB270+'All_India_Index_Upto_April23 (1'!AC270+'All_India_Index_Upto_April23 (1'!AD270 -> 742 | M270: =D270+E270+F270+G270+H270+I270+J270+K270+L270 -> 4066.2 | N270: =D270/M270*100 -> 40.416113 | O270: =E270/M270*100 -> 8.6468939 | P270: =F270/M270*100 -> 4.5915105 | Q270: =G270/M270*100 -> 10.646304 | R270: =H270/M270*100 -> 7.2573902 | S270: =I270/M270*100 -> 3.3716984 | T270: =J270/M270*100 -> 3.6422212 | U270: =K270/M270*100 -> 3.1798731 | V270: =L270/M270*100 -> 18.247996 | W270: =N270+O270+P270+Q270+R270+S270+T270+U270+V270 -> 100
A271: Rural+Urban | B271: 2020 | C271: July | D271: ='All_India_Index_Upto_April23 (1'!D271+'All_India_Index_Upto_April23 (1'!G271+'All_India_Index_Upto_April23 (1'!H271+'All_India_Index_Upto_April23 (1'!I271+'All_India_Index_Upto_April23 (1'!J271+'All_India_Index_Upto_April23 (1'!K271+'All_India_Index_Upto_April23 (1'!L271+'All_India_Index_Upto_April23 (1'!M271+'All_India_Index_Upto_April23 (1'!N271+'All_India_Index_Upto_April23 (1'!O271+'All_India_Index_Upto_April23 (1'!P271 -> 1622.7 | E271: ='All_India_Index_Upto_April23 (1'!E271+'All_India_Index_Upto_April23 (1'!F271 -> 344.1 | F271: 183.5 | G271: ='All_India_Index_Upto_April23 (1'!R271+'All_India_Index_Upto_April23 (1'!S271+'All_India_Index_Upto_April23 (1'!T271 -> 448.3 | H271: ='All_India_Index_Upto_April23 (1'!U271+'All_India_Index_Upto_April23 (1'!W271 -> 301.1 | I271: 141.9 | J271: 154.4 | K271: 135 | L271: ='All_India_Index_Upto_April23 (1'!Z271+'All_India_Index_Upto_April23 (1'!AA271+'All_India_Index_Upto_April23 (1'!AB271+'All_India_Index_Upto_April23 (1'!AC271+'All_India_Index_Upto_April23 (1'!AD271 -> 755.1 | M271: =D271+E271+F271+G271+H271+I271+J271+K271+L271 -> 4086.1 | N271: =D271/M271*100 -> 39.712684 | O271: =E271/M271*100 -> 8.421233 | P271: =F271/M271*100 -> 4.4908348 | Q271: =G271/M271*100 -> 10.971342 | R271: =H271/M271*100 -> 7.3688848 | S271: =I271/M271*100 -> 3.4727491 | T271: =J271/M271*100 -> 3.7786643 | U271: =K271/M271*100 -> 3.3038839 | V271: =L271/M271*100 -> 18.479724 | W271: =N271+O271+P271+Q271+R271+S271+T271+U271+V271 -> 100
A272: Rural | B272: 2020 | C272: August | D272: ='All_India_Index_Upto_April23 (1'!D272+'All_India_Index_Upto_April23 (1'!G272+'All_India_Index_Upto_April23 (1'!H272+'All_India_Index_Upto_April23 (1'!I272+'All_India_Index_Upto_April23 (1'!J272+'All_India_Index_Upto_April23 (1'!K272+'All_India_Index_Upto_April23 (1'!L272+'All_India_Index_Upto_April23 (1'!M272+'All_India_Index_Upto_April23 (1'!N272+'All_India_Index_Upto_April23 (1'!O272+'All_India_Index_Upto_April23 (1'!P272 -> 1643 | E272: ='All_India_Index_Upto_April23 (1'!E272+'All_India_Index_Upto_April23 (1'!F272 -> 335.6 | F272: 180.9 | G272: ='All_India_Index_Upto_April23 (1'!R272+'All_India_Index_Upto_April23 (1'!S272+'All_India_Index_Upto_April23 (1'!T272 -> 458.7 | H272: ='All_India_Index_Upto_April23 (1'!U272+'All_India_Index_Upto_April23 (1'!W272 -> 151.9 | I272: 145.8 | J272: 158.8 | K272: 143.6 | L272: ='All_India_Index_Upto_April23 (1'!Z272+'All_India_Index_Upto_April23 (1'!AA272+'All_India_Index_Upto_April23 (1'!AB272+'All_India_Index_Upto_April23 (1'!AC272+'All_India_Index_Upto_April23 (1'!AD272 -> 776.2 | M272: =D272+E272+F272+G272+H272+I272+J272+K272+L272 -> 3994.5 | N272: =D272/M272*100 -> 41.131556 | O272: =E272/M272*100 -> 8.4015521 | P272: =F272/M272*100 -> 4.528727 | Q272: =G272/M272*100 -> 11.48329 | R272: =H272/M272*100 -> 3.8027288 | S272: =I272/M272*100 -> 3.6500188 | T272: =J272/M272*100 -> 3.9754663 | U272: =K272/M272*100 -> 3.594943 | V272: =L272/M272*100 -> 19.431719 | W272: =N272+O272+P272+Q272+R272+S272+T272+U272+V272 -> 100
A273: Urban | B273: 2020 | C273: August | D273: ='All_India_Index_Upto_April23 (1'!D273+'All_India_Index_Upto_April23 (1'!G273+'All_India_Index_Upto_April23 (1'!H273+'All_India_Index_Upto_April23 (1'!I273+'All_India_Index_Upto_April23 (1'!J273+'All_India_Index_Upto_April23 (1'!K273+'All_India_Index_Upto_April23 (1'!L273+'All_India_Index_Upto_April23 (1'!M273+'All_India_Index_Upto_April23 (1'!N273+'All_India_Index_Upto_April23 (1'!O273+'All_India_Index_Upto_April23 (1'!P273 -> 1672.6 | E273: ='All_India_Index_Upto_April23 (1'!E273+'All_India_Index_Upto_April23 (1'!F273 -> 352.3 | F273: 187.2 | G273: ='All_India_Index_Upto_April23 (1'!R273+'All_India_Index_Upto_April23 (1'!S273+'All_India_Index_Upto_April23 (1'!T273 -> 433 | H273: ='All_India_Index_Upto_April23 (1'!U273+'All_India_Index_Upto_April23 (1'!W273 -> 300 | I273: 138.3 | J273: 148.7 | K273: 133.9 | L273: ='All_India_Index_Upto_April23 (1'!Z273+'All_India_Index_Upto_April23 (1'!AA273+'All_India_Index_Upto_April23 (1'!AB273+'All_India_Index_Upto_April23 (1'!AC273+'All_India_Index_Upto_April23 (1'!AD273 -> 749.6 | M273: =D273+E273+F273+G273+H273+I273+J273+K273+L273 -> 4115.6 | N273: =D273/M273*100 -> 40.64049 | O273: =E273/M273*100 -> 8.5601127 | P273: =F273/M273*100 -> 4.548547 | Q273: =G273/M273*100 -> 10.520945 | R273: =H273/M273*100 -> 7.2893381 | S273: =I273/M273*100 -> 3.3603849 | T273: =J273/M273*100 -> 3.6130819 | U273: =K273/M273*100 -> 3.2534746 | V273: =L273/M273*100 -> 18.213626 | W273: =N273+O273+P273+Q273+R273+S273+T273+U273+V273 -> 100
A274: Rural+Urban | B274: 2020 | C274: August | D274: ='All_India_Index_Upto_April23 (1'!D274+'All_India_Index_Upto_April23 (1'!G274+'All_India_Index_Upto_April23 (1'!H274+'All_India_Index_Upto_April23 (1'!I274+'All_India_Index_Upto_April23 (1'!J274+'All_India_Index_Upto_April23 (1'!K274+'All_India_Index_Upto_April23 (1'!L274+'All_India_Index_Upto_April23 (1'!M274+'All_India_Index_Upto_April23 (1'!N274+'All_India_Index_Upto_April23 (1'!O274+'All_India_Index_Upto_April23 (1'!P274 -> 1653.5 | E274: ='All_India_Index_Upto_April23 (1'!E274+'All_India_Index_Upto_April23 (1'!F274 -> 341.7 | F274: 182.6 | G274: ='All_India_Index_Upto_April23 (1'!R274+'All_India_Index_Upto_April23 (1'!S274+'All_India_Index_Upto_April23 (1'!T274 -> 448.2 | H274: ='All_India_Index_Upto_April23 (1'!U274+'All_India_Index_Upto_April23 (1'!W274 -> 303.9 | I274: 143 | J274: 155 | K274: 138.5 | L274: ='All_India_Index_Upto_April23 (1'!Z274+'All_India_Index_Upto_April23 (1'!AA274+'All_India_Index_Upto_April23 (1'!AB274+'All_India_Index_Upto_April23 (1'!AC274+'All_India_Index_Upto_April23 (1'!AD274 -> 761.7 | M274: =D274+E274+F274+G274+H274+I274+J274+K274+L274 -> 4128.1 | N274: =D274/M274*100 -> 40.054747 | O274: =E274/M274*100 -> 8.2774158 | P274: =F274/M274*100 -> 4.4233425 | Q274: =G274/M274*100 -> 10.857295 | R274: =H274/M274*100 -> 7.3617403 | S274: =I274/M274*100 -> 3.4640634 | T274: =J274/M274*100 -> 3.754754 | U274: =K274/M274*100 -> 3.3550544 | V274: =L274/M274*100 -> 18.451588 | W274: =N274+O274+P274+Q274+R274+S274+T274+U274+V274 -> 100
A275: Rural | B275: 2020 | C275: September | D275: ='All_India_Index_Upto_April23 (1'!D275+'All_India_Index_Upto_April23 (1'!G275+'All_India_Index_Upto_April23 (1'!H275+'All_India_Index_Upto_April23 (1'!I275+'All_India_Index_Upto_April23 (1'!J275+'All_India_Index_Upto_April23 (1'!K275+'All_India_Index_Upto_April23 (1'!L275+'All_India_Index_Upto_April23 (1'!M275+'All_India_Index_Upto_April23 (1'!N275+'All_India_Index_Upto_April23 (1'!O275+'All_India_Index_Upto_April23 (1'!P275 -> 1654 | E275: ='All_India_Index_Upto_April23 (1'!E275+'All_India_Index_Upto_April23 (1'!F275 -> 333.4 | F275: 182.9 | G275: ='All_India_Index_Upto_April23 (1'!R275+'All_India_Index_Upto_April23 (1'!S275+'All_India_Index_Upto_April23 (1'!T275 -> 459.9 | H275: ='All_India_Index_Upto_April23 (1'!U275+'All_India_Index_Upto_April23 (1'!W275 -> 151.6 | I275: 146.4 | J275: 159.1 | K275: 144.6 | L275: ='All_India_Index_Upto_April23 (1'!Z275+'All_India_Index_Upto_April23 (1'!AA275+'All_India_Index_Upto_April23 (1'!AB275+'All_India_Index_Upto_April23 (1'!AC275+'All_India_Index_Upto_April23 (1'!AD275 -> 780.4 | M275: =D275+E275+F275+G275+H275+I275+J275+K275+L275 -> 4012.3 | N275: =D275/M275*100 -> 41.223239 | O275: =E275/M275*100 -> 8.3094484 | P275: =F275/M275*100 -> 4.5584827 | Q275: =G275/M275*100 -> 11.462254 | R275: =H275/M275*100 -> 3.7783815 | S275: =I275/M275*100 -> 3.64878 | T275: =J275/M275*100 -> 3.9653067 | U275: =K275/M275*100 -> 3.603918 | V275: =L275/M275*100 -> 19.450191 | W275: =N275+O275+P275+Q275+R275+S275+T275+U275+V275 -> 100
A276: Urban | B276: 2020 | C276: September | D276: ='All_India_Index_Upto_April23 (1'!D276+'All_India_Index_Upto_April23 (1'!G276+'All_India_Index_Upto_April23 (1'!H276+'All_India_Index_Upto_April23 (1'!I276+'All_India_Index_Upto_April23 (1'!J276+'All_India_Index_Upto_April23 (1'!K276+'All_India_Index_Upto_April23 (1'!L276+'All_India_Index_Upto_April23 (1'!M276+'All_India_Index_Upto_April23 (1'!N276+'All_India_Index_Upto_April23 (1'!O276+'All_India_Index_Upto_April23 (1'!P276 -> 1691.2 | E276: ='All_India_Index_Upto_April23 (1'!E276+'All_India_Index_Upto_April23 (1'!F276 -> 350.4 | F276: 188.7 | G276: ='All_India_Index_Upto_April23 (1'!R276+'All_India_Index_Upto_April23 (1'!S276+'All_India_Index_Upto_April23 (1'!T276 -> 434.6 | H276: ='All_India_Index_Upto_April23 (1'!U276+'All_India_Index_Upto_April23 (1'!W276 -> 301.7 | I276: 137.2 | J276: 150 | K276: 135.1 | L276: ='All_India_Index_Upto_April23 (1'!Z276+'All_India_Index_Upto_April23 (1'!AA276+'All_India_Index_Upto_April23 (1'!AB276+'All_India_Index_Upto_April23 (1'!AC276+'All_India_Index_Upto_April23 (1'!AD276 -> 756.5 | M276: =D276+E276+F276+G276+H276+I276+J276+K276+L276 -> 4145.4 | N276: =D276/M276*100 -> 40.797028 | O276: =E276/M276*100 -> 8.4527428 | P276: =F276/M276*100 -> 4.5520336 | Q276: =G276/M276*100 -> 10.48391 | R276: =H276/M276*100 -> 7.2779466 | S276: =I276/M276*100 -> 3.3096927 | T276: =J276/M276*100 -> 3.6184687 | U276: =K276/M276*100 -> 3.2590341 | V276: =L276/M276*100 -> 18.249144 | W276: =N276+O276+P276+Q276+R276+S276+T276+U276+V276 -> 100
A277: Rural+Urban | B277: 2020 | C277: September | D277: ='All_India_Index_Upto_April23 (1'!D277+'All_India_Index_Upto_April23 (1'!G277+'All_India_Index_Upto_April23 (1'!H277+'All_India_Index_Upto_April23 (1'!I277+'All_India_Index_Upto_April23 (1'!J277+'All_India_Index_Upto_April23 (1'!K277+'All_India_Index_Upto_April23 (1'!L277+'All_India_Index_Upto_April23 (1'!M277+'All_India_Index_Upto_April23 (1'!N277+'All_India_Index_Upto_April23 (1'!O277+'All_India_Index_Upto_April23 (1'!P277 -> 1667.4 | E277: ='All_India_Index_Upto_April23 (1'!E277+'All_India_Index_Upto_April23 (1'!F277 -> 339.6 | F277: 184.4 | G277: ='All_India_Index_Upto_April23 (1'!R277+'All_India_Index_Upto_April23 (1'!S277+'All_India_Index_Upto_April23 (1'!T277 -> 449.7 | H277: ='All_India_Index_Upto_April23 (1'!U277+'All_India_Index_Upto_April23 (1'!W277 -> 305 | I277: 142.9 | J277: 155.6 | K277: 139.6 | L277: ='All_India_Index_Upto_April23 (1'!Z277+'All_India_Index_Upto_April23 (1'!AA277+'All_India_Index_Upto_April23 (1'!AB277+'All_India_Index_Upto_April23 (1'!AC277+'All_India_Index_Upto_April23 (1'!AD277 -> 767.2 | M277: =D277+E277+F277+G277+H277+I277+J277+K277+L277 -> 4151.4 | N277: =D277/M277*100 -> 40.164764 | O277: =E277/M277*100 -> 8.1803729 | P277: =F277/M277*100 -> 4.441875 | Q277: =G277/M277*100 -> 10.83249 | R277: =H277/M277*100 -> 7.3469191 | S277: =I277/M277*100 -> 3.4422123 | T277: =J277/M277*100 -> 3.7481332 | U277: =K277/M277*100 -> 3.362721 | V277: =L277/M277*100 -> 18.480513 | W277: =N277+O277+P277+Q277+R277+S277+T277+U277+V277 -> 100
... A367: Rural+Urban | B367: 2023 | C367: March | D367: ='All_India_Index_Upto_April23 (1'!D367+'All_India_Index_Upto_April23 (1'!G367+'All_India_Index_Upto_April23 (1'!H367+'All_India_Index_Upto_April23 (1'!I367+'All_India_Index_Upto_April23 (1'!J367+'All_India_Index_Upto_April23 (1'!K367+'All_India_Index_Upto_April23 (1'!L367+'All_India_Index_Upto_April23 (1'!M367+'All_India_Index_Upto_April23 (1'!N367+'All_India_Index_Upto_April23 (1'!O367+'All_India_Index_Upto_April23 (1'!P367 -> 1896.3 | E367: ='All_India_Index_Upto_April23 (1'!E367+'All_India_Index_Upto_April23 (1'!F367 -> 382.9 | F367: 199.5 | G367: ='All_India_Index_Upto_April23 (1'!R367+'All_India_Index_Upto_April23 (1'!S367+'All_India_Index_Upto_April23 (1'!T367 -> 549.9 | H367: ='All_India_Index_Upto_April23 (1'!U367+'All_India_Index_Upto_April23 (1'!W367 -> 347.7 | I367: 181.9 | J367: 184.4 | K367: 164.2 | L367: ='All_India_Index_Upto_April23 (1'!Z367+'All_India_Index_Upto_April23 (1'!AA367+'All_India_Index_Upto_April23 (1'!AB367+'All_India_Index_Upto_April23 (1'!AC367+'All_India_Index_Upto_April23 (1'!AD367 -> 877.6 | M367: =D367+E367+F367+G367+H367+I367+J367+K367+L367 -> 4784.4 | N367: =D367/M367*100 -> 39.635064 | O367: =E367/M367*100 -> 8.0030934 | P367: =F367/M367*100 -> 4.1698019 | Q367: =G367/M367*100 -> 11.493604 | R367: =H367/M367*100 -> 7.2673689 | S367: =I367/M367*100 -> 3.8019396 | T367: =J367/M367*100 -> 3.8541928 | U367: =K367/M367*100 -> 3.4319873 | V367: =L367/M367*100 -> 18.342948 | W367: =N367+O367+P367+Q367+R367+S367+T367+U367+V367 -> 100
